<robot name = "flip_5link">
  <material name = "link-color">
	<color rgba = "0.5 0.5 0.5 1" />
  </material>
  <material name = "Hebi-X-color">
    <color rgba = "1 0.27 0 1" />
  </material>
  <material name = "Hebi-X-color2">
    <color rgba = "0.9 0.3 0 1" />
  </material>


  <link name = "world">
  </link>

  <joint name="world_joint" type="revolute">
    <parent link="world"/>
    <child link="left_shank"/>
    <origin rpy="0.0 0.0 0.0" xyz="0.0 0.0 0.0"/>
    <limit lower="-1" upper="1" velocity="2.5" effort="0.0"/>
		<axis xyz = "0 1 0" />
  </joint>

  <link name = "left_shank">
		<inertial>
			<origin rpy = "0 -1.57075 0" xyz = "-0.1635 0 0" />
			<mass value = "0.3037" />
			<inertia ixx = "0.1" iyy = "0.1" izz = "0.00398"
	ixy = "0" ixz = "0" iyz = "0" />
		</inertial>
		<visual>
          <origin rpy = "0 -1.57075 0" xyz = "-0.1635 0 0"/> <!-- CoM frame rotate -->
			<geometry>
			  <cylinder radius = "0.02" length = "0.288"/> <!-- total 0.308 (cylinder + phere) -->
			</geometry>
			<material name = "link-color"/>
		</visual>
        <visual>
          <origin rpy = "0 0 0" xyz = "-0.01 0 0"/>
			<geometry>
			  <sphere radius = "0.02"/>
			</geometry>
            <!-- <material name = "link-color"/> -->
            <material name = "Hebi-X-color"/>
        </visual>
  </link>


  <joint name = "left_knee" type = "revolute">
		<parent link = "left_shank" />
		<child link = "left_thigh" />
	    <origin rpy = "1.57075 0 0" xyz = "-0.308 0.045 0" /> <!-- relative to ankle joint -->
		<axis xyz = "0 0 1" />
        <limit lower="0.0" upper="0.548" velocity="0.5" effort="30.0"/>
  </joint>


  <link name = "left_thigh">
		<inertial>
			<origin rpy = "0  1.57075  0" xyz = "-0.0579 0 0" />  <!-- 0.2755-0.2176 -->
			<mass value = "0.8112" />
			<inertia ixx = "0.1" iyy = "0.1" izz = "0.00709"
	ixy = "0" ixz = "0" iyz = "0" />
		</inertial>
		<visual>
		    <origin rpy = "0  1.57075  0" xyz = "-0.1378 0 0"/> <!-- CoM relative to knee joint -->
			<geometry>
			  <cylinder radius = "0.02" length = "0.2755"  />
			</geometry>
			<material name = "link-color"/>
		</visual>
        <!-- Left knee motor -->
        <visual>
          <origin xyz = "-0.035  0  0.04225"/> <!-- 0.2755 - 0.2405  -->
          <geometry>
            <box size = "0.11 0.075 0.045" />
          </geometry>
          <material name = "Hebi-X-color2"/>
        </visual>
  </link>

  <joint name = "left_hip" type = "revolute">
		<parent link = "left_thigh" />
		<child link = "base" />
	    <origin rpy = "3.1416 0  0" xyz = "-0.2755 0 0" />
		<axis xyz = "0 0 1" />
        <limit lower="0.0" upper="0.548" velocity="0.5" effort="30.0"/>
  </joint>

  <link name = "base">
		<inertial>
			<origin rpy = "1.57075 0 0" xyz = "0 -0.1125 -0.265" />
			<mass value = "5.354" />
			<inertia ixx = "0.1" iyy = "0.02517" izz = "0.5"
                     ixy = "0" ixz = "0" iyz = "0" />
		</inertial>
		<visual>
			<origin rpy = "1.57075 0 0" xyz = "0 -0.1125 -0.265" />
			<geometry>
			  <box size = "0.1 0.4 0.3" />
			</geometry>
            <material name = "link-color"/>
		</visual>
        <!-- Left hip motor -->
        <visual>
          <origin rpy = "1.57075 0 0" xyz = "0 0 -0.0425" /> <!--0.265-0.2225-->
          <geometry>
            <box size = "0.11 0.045 0.075" />
          </geometry>
          <material name = "Hebi-X-color"/>
        </visual>
        <!-- Right hip motor -->
        <visual>
          <origin rpy = "1.57075 0 0" xyz = "0 0 -0.4875" /> <!--0.265+0.2225-->
          <geometry>
            <box size = "0.11 0.045 0.075" />
          </geometry>
          <material name = "Hebi-X-color"/>
        </visual>
  </link>

  <joint name = "right_hip" type = "revolute">
		<parent link = "base" />
		<child link = "right_thigh" />
	    <origin rpy = "3.1416 0  0" xyz = "0. 0 -0.53" /> <!--relative to last joint-->
		<axis xyz = "0 0 1" />
        <limit lower="0.0" upper="0.548" velocity="0.5" effort="30.0"/>
  </joint>

  <link name = "right_thigh">
		<inertial>
			<origin rpy = "0 1.57075 0" xyz = "0.2176 0 0" />
			<mass value = "0.8112" />
			<inertia ixx = "0.1" iyy = "0.1" izz = "0.00709"
	ixy = "0" ixz = "0" iyz = "0" />
		</inertial>
		<visual>
          <origin rpy = "0 1.57075 0" xyz = "0.138 0 0"/>
			<geometry>
			  <cylinder radius = "0.02" length = "0.2755"  />
			</geometry>
			<material name = "link-color"/>
		</visual>
        <!-- right knee motor -->
        <visual>
          <origin xyz = "0.2405 0 -0.04225"/>
          <geometry>
            <box size = "0.11 0.075 0.045" />
          </geometry>
          <material name = "Hebi-X-color2"/>
        </visual>
  </link>

  <joint name = "right_knee" type = "revolute">
		<parent link = "right_thigh" />
		<child link = "right_shank" />
	    <origin rpy = "3.141592 0 0" xyz = "0.2755 0 -0.045" />
		<axis xyz = "0 0 1" />
        <limit lower="0.0" upper="0.548" velocity="0.5" effort="30.0"/>
  </joint>

  <link name = "right_shank">
		<inertial>
			<origin xyz = "0.1445 0 0" />
			<mass value = "0.3037" />
			<inertia ixx = "0.1" iyy = "0.1" izz = "0.00398"
	ixy = "0" ixz = "0" iyz = "0" />
		</inertial>
		<visual>
          <origin rpy = "0 1.57075 0" xyz = "0.144 0 0"/>
			<geometry>
			  <cylinder radius = "0.02" length = "0.288"/> <!-- total 0.308 (cylinder + phere) -->
			</geometry>
			<material name = "link-color"/>
		</visual>
        <visual>
          <origin rpy = "0 0 0" xyz = "0.288 0 0"/>
			<geometry>
			  <sphere radius = "0.02"/>
			</geometry>
            <!-- <material name = "link-color"/> -->
            <material name = "Hebi-X-color"/>
        </visual>
  </link>








</robot>
